Workbook

Sheet Reference summary
A2: REVISED V4 — PART SIZE → TOOL BLOCK SIZE → BLOCK COUNT
A4: Process | B4: GENERIC PART — dimensions in mm | C4: Length | D4: Width | E4: Height | F4: Thickness | G4: Tool component and MALE / FEMALE role | H4: NUMBER OF BLOCKS of this size | I4: RAW STOCK TO ORDER — per block (mm) | J4: RAW BLOCK length (mm) | K4: RAW BLOCK width (mm) | L4: RAW BLOCK thickness (mm) | M4: ROUND BILLET diameter (mm) | N4: PART envelope length (mm) | O4: PART envelope width (mm) | P4: PART envelope height (mm) | Q4: PART outer diameter (mm) | R4: PART wall / sheet thickness (mm) | S4: TOTAL MACHINED BLOCKS per reference tool set | T4: Tooling Stock form | U4: Tooling Raw Material Grade | V4: Sizing basis / scope
A5: Bending | B5: L-bracket: bend 100; legs 50 × 50; sheet 2 | C5: 100 | D5: 50 | E5: 50 | F5: 2 | G5: MALE — Bending punch | H5: ='Tool blocks'!E5 -> 1 | I5: =IF(H5=0,"Purchased assembly",IF(T5="Round billet","Ø"&M5&" × "&J5,J5&" × "&K5&" × "&L5)) -> 120 × 40 × 90 | J5: ='Tool blocks'!X5 -> 120 | K5: ='Tool blocks'!Y5 -> 40 | L5: ='Tool blocks'!Z5 -> 90 | M5: ="n.a." -> n.a. | N5: 100 | O5: 50 | P5: 50 | Q5: n.a. | R5: 2 | S5: 0.5 | T5: Rectangular block | U5: DC01 steel | V5: Custom punch/die working bodies only; mounting interfaces need confirmation.
A6: Bending | B6: L-bracket: bend 100; legs 50 × 50; sheet 2 | C6: 100 | D6: 50 | E6: 50 | F6: 2 | G6: FEMALE DIE — V-die | H6: ='Tool blocks'!E6 -> 1 | I6: =IF(H6=0,"Purchased assembly",IF(T6="Round billet","Ø"&M6&" × "&J6,J6&" × "&K6&" × "&L6)) -> 120 × 50 × 45 | J6: ='Tool blocks'!X6 -> 120 | K6: ='Tool blocks'!Y6 -> 50 | L6: ='Tool blocks'!Z6 -> 45 | M6: ="n.a." -> n.a. | N6: 100 | O6: 50 | P6: 50 | Q6: n.a. | R6: 2 | S6: 0.5 | T6: Rectangular block | U6: DC01 steel | V6: Custom punch/die working bodies only; mounting interfaces need confirmation.
A7: Metal extrusion | B7: Square tube: 40 × 40 × wall 3; length 1000 | C7: 1000 | D7: 40 | E7: 40 | F7: 3 | G7: FEMALE DIE — Profile die disk | H7: ='Tool blocks'!E17 -> 1 | I7: =IF(H7=0,"Purchased assembly",IF(T7="Round billet","Ø"&M7&" × "&J7,J7&" × "&K7&" × "&L7)) -> Ø190 × 70 | J7: ='Tool blocks'!Z17 -> 70 | K7: ="n.a." -> n.a. | L7: ="n.a." -> n.a. | M7: ='Tool blocks'!X17 -> 190 | N7: 1000 | O7: 40 | P7: 40 | Q7: n.a. | R7: 3 | S7: 0.33333333 | T7: Round billet | U7: EN AW-6063 aluminum | V7: Illustrative Ø180 mm die package; actual press container and holder govern outside diameter.
A8: Metal extrusion | B8: Square tube: 40 × 40 × wall 3; length 1000 | C8: 1000 | D8: 40 | E8: 40 | F8: 3 | G8: MALE / BRIDGE — Bridge plate with integral mandrel | H8: ='Tool blocks'!E18 -> 1 | I8: =IF(H8=0,"Purchased assembly",IF(T8="Round billet","Ø"&M8&" × "&J8,J8&" × "&K8&" × "&L8)) -> Ø190 × 70 | J8: ='Tool blocks'!Z18 -> 70 | K8: ="n.a." -> n.a. | L8: ="n.a." -> n.a. | M8: ='Tool blocks'!X18 -> 190 | N8: 1000 | O8: 40 | P8: 40 | Q8: n.a. | R8: 3 | S8: 0.33333333 | T8: Round billet | U8: EN AW-6063 aluminum | V8: Illustrative Ø180 mm die package; actual press container and holder govern outside diameter.
A9: Metal extrusion | B9: Square tube: 40 × 40 × wall 3; length 1000 | C9: 1000 | D9: 40 | E9: 40 | F9: 3 | G9: SUPPORT — Die backer | H9: ='Tool blocks'!E19 -> 1 | I9: =IF(H9=0,"Purchased assembly",IF(T9="Round billet","Ø"&M9&" × "&J9,J9&" × "&K9&" × "&L9)) -> Ø190 × 50 | J9: ='Tool blocks'!Z19 -> 50 | K9: ="n.a." -> n.a. | L9: ="n.a." -> n.a. | M9: ='Tool blocks'!X19 -> 190 | N9: 1000 | O9: 40 | P9: 40 | Q9: n.a. | R9: 3 | S9: 0.33333333 | T9: Round billet | U9: EN AW-6063 aluminum | V9: Illustrative Ø180 mm die package; actual press container and holder govern outside diameter.
A10: Die casting | B10: Open hemisphere: Ø100 × depth 50; wall 3 | C10: 100 | D10: 100 | E10: 50 | F10: 3 | G10: FEMALE — Outer hemisphere cavity | H10: ='Tool blocks'!E35 -> 1 | I10: =IF(H10=0,"Purchased assembly",IF(T10="Round billet","Ø"&M10&" × "&J10,J10&" × "&K10&" × "&L10)) -> 190 × 190 × 100 | J10: ='Tool blocks'!X35 -> 190 | K10: ='Tool blocks'!Y35 -> 190 | L10: ='Tool blocks'!Z35 -> 100 | M10: ="n.a." -> n.a. | N10: 100 | O10: 100 | P10: 50 | Q10: 100 | R10: 3 | S10: 0.5 | T10: Rectangular block | U10: A380 aluminum | V10: Working inserts only. Mold base, feed/ejection hardware and any joining fixture are additional.
A11: Die casting | B11: Open hemisphere: Ø100 × depth 50; wall 3 | C11: 100 | D11: 100 | E11: 50 | F11: 3 | G11: MALE — Inner hemisphere core | H11: ='Tool blocks'!E36 -> 1 | I11: =IF(H11=0,"Purchased assembly",IF(T11="Round billet","Ø"&M11&" × "&J11,J11&" × "&K11&" × "&L11)) -> 175 × 175 × 90 | J11: ='Tool blocks'!X36 -> 175 | K11: ='Tool blocks'!Y36 -> 175 | L11: ='Tool blocks'!Z36 -> 90 | M11: ="n.a." -> n.a. | N11: 100 | O11: 100 | P11: 50 | Q11: 100 | R11: 3 | S11: 0.5 | T11: Rectangular block | U11: A380 aluminum | V11: Working inserts only. Mold base, feed/ejection hardware and any joining fixture are additional.
A12: Sand casting | B12: Solid sphere: Ø100 | C12: 100 | D12: 100 | E12: 100 | F12: n.a | G12: MALE PATTERN — Positive hemisphere pattern | H12: ='Tool blocks'!E47 -> 2 | I12: =IF(H12=0,"Purchased assembly",IF(T12="Round billet","Ø"&M12&" × "&J12,J12&" × "&K12&" × "&L12)) -> 110 × 110 × 70 | J12: ='Tool blocks'!X47 -> 110 | K12: ='Tool blocks'!Y47 -> 110 | L12: ='Tool blocks'!Z47 -> 70 | M12: ="n.a." -> n.a. | N12: 100 | O12: 100 | P12: 100 | Q12: 100 | R12: n.a. | S12: 0.66666667 | T12: Rectangular block | U12: EN-GJL-250 gray cast iron | V12: Machined aluminum pattern route selected. Wood/resin or printed sand remain alternative routes, not additional blocks.
A13: Sand casting | B13: Solid sphere: Ø100 | C13: 100 | D13: 100 | E13: 100 | F13: n.a | G13: SUPPORT — Pattern mounting plate | H13: ='Tool blocks'!E48 -> 1 | I13: =IF(H13=0,"Purchased assembly",IF(T13="Round billet","Ø"&M13&" × "&J13,J13&" × "&K13&" × "&L13)) -> 180 × 180 × 30 | J13: ='Tool blocks'!X48 -> 180 | K13: ='Tool blocks'!Y48 -> 180 | L13: ='Tool blocks'!Z48 -> 30 | M13: ="n.a." -> n.a. | N13: 100 | O13: 100 | P13: 100 | Q13: 100 | R13: n.a. | S13: 0.33333333 | T13: Rectangular block | U13: EN-GJL-250 gray cast iron | V13: Machined aluminum pattern route selected. Wood/resin or printed sand remain alternative routes, not additional blocks.
A14: Investment casting | B14: Solid sphere: Ø100 (wax-pattern tooling) | C14: 100 | D14: 100 | E14: 100 | F14: n.a | G14: FEMALE — Wax-mold hemisphere half | H14: ='Tool blocks'!E59 -> 2 | I14: =IF(H14=0,"Purchased assembly",IF(T14="Round billet","Ø"&M14&" × "&J14,J14&" × "&K14&" × "&L14)) -> 170 × 170 × 90 | J14: ='Tool blocks'!X59 -> 170 | K14: ='Tool blocks'!Y59 -> 170 | L14: ='Tool blocks'!Z59 -> 90 | M14: ="n.a." -> n.a. | N14: 100 | O14: 100 | P14: 100 | Q14: 100 | R14: n.a. | S14: 1 | T14: Rectangular block | U14: Cast 316L stainless steel | V14: Wax-injection mold blocks only; 2% total tool-size enlargement is an estimating assumption, not a qualified shrinkage value.
A15: Closed die forging | B15: Solid sphere: Ø100 (forging) | C15: 100 | D15: 100 | E15: 100 | F15: n.a | G15: FEMALE DIE — Forging impression half | H15: ='Tool blocks'!E65 -> 2 | I15: =IF(H15=0,"Purchased assembly",IF(T15="Round billet","Ø"&M15&" × "&J15,J15&" × "&K15&" × "&L15)) -> 210 × 210 × 130 | J15: ='Tool blocks'!X65 -> 210 | K15: ='Tool blocks'!Y65 -> 210 | L15: ='Tool blocks'!Z65 -> 130 | M15: ="n.a." -> n.a. | N15: 100 | O15: 100 | P15: 100 | Q15: 100 | R15: n.a. | S15: 0.5 | T15: Rectangular block | U15: C45 steel | V15: Finishing and trimming tools shown. Billet preparation or blocker tooling may be additional.
A16: Closed die forging | B16: Solid sphere: Ø100 (forging) | C16: 100 | D16: 100 | E16: 100 | F16: n.a | G16: MALE — Trimming punch | H16: ='Tool blocks'!E66 -> 1 | I16: =IF(H16=0,"Purchased assembly",IF(T16="Round billet","Ø"&M16&" × "&J16,J16&" × "&K16&" × "&L16)) -> Ø110 × 70 | J16: ='Tool blocks'!Z66 -> 70 | K16: ="n.a." -> n.a. | L16: ="n.a." -> n.a. | M16: ='Tool blocks'!X66 -> 110 | N16: 100 | O16: 100 | P16: 100 | Q16: 100 | R16: n.a. | S16: 0.25 | T16: Round billet | U16: C45 steel | V16: Finishing and trimming tools shown. Billet preparation or blocker tooling may be additional.
A17: Closed die forging | B17: Solid sphere: Ø100 (forging) | C17: 100 | D17: 100 | E17: 100 | F17: n.a | G17: FEMALE DIE — Trimming die | H17: ='Tool blocks'!E67 -> 1 | I17: =IF(H17=0,"Purchased assembly",IF(T17="Round billet","Ø"&M17&" × "&J17,J17&" × "&K17&" × "&L17)) -> 180 × 180 × 50 | J17: ='Tool blocks'!X67 -> 180 | K17: ='Tool blocks'!Y67 -> 180 | L17: ='Tool blocks'!Z67 -> 50 | M17: ="n.a." -> n.a. | N17: 100 | O17: 100 | P17: 100 | Q17: 100 | R17: n.a. | S17: 0.25 | T17: Rectangular block | U17: C45 steel | V17: Finishing and trimming tools shown. Billet preparation or blocker tooling may be additional.
A18: Plastic extrusion | B18: Rectangular tube: 40 × 25 × wall 2; length 1000 | C18: 1000 | D18: 40 | E18: 25 | F18: 2 | G18: FEMALE DIE — Profile die block | H18: ='Tool blocks'!E83 -> 1 | I18: =IF(H18=0,"Purchased assembly",IF(T18="Round billet","Ø"&M18&" × "&J18,J18&" × "&K18&" × "&L18)) -> 130 × 115 × 60 | J18: ='Tool blocks'!X83 -> 130 | K18: ='Tool blocks'!Y83 -> 115 | L18: ='Tool blocks'!Z83 -> 60 | M18: ="n.a." -> n.a. | N18: 1000 | O18: 40 | P18: 25 | Q18: n.a. | R18: 2 | S18: 0.33333333 | T18: Rectangular block | U18: Rigid PVC | V18: Illustrative compact profile head; upstream distributor and screw/barrel are separate.
A19: Plastic extrusion | B19: Rectangular tube: 40 × 25 × wall 2; length 1000 | C19: 1000 | D19: 40 | E19: 25 | F19: 2 | G19: MALE — Profile mandrel | H19: ='Tool blocks'!E84 -> 1 | I19: =IF(H19=0,"Purchased assembly",IF(T19="Round billet","Ø"&M19&" × "&J19,J19&" × "&K19&" × "&L19)) -> 45 × 30 × 110 | J19: ='Tool blocks'!X84 -> 45 | K19: ='Tool blocks'!Y84 -> 30 | L19: ='Tool blocks'!Z84 -> 110 | M19: ="n.a." -> n.a. | N19: 1000 | O19: 40 | P19: 25 | Q19: n.a. | R19: 2 | S19: 0.33333333 | T19: Rectangular block | U19: Rigid PVC | V19: Illustrative compact profile head; upstream distributor and screw/barrel are separate.
A20: Plastic extrusion | B20: Rectangular tube: 40 × 25 × wall 2; length 1000 | C20: 1000 | D20: 40 | E20: 25 | F20: 2 | G20: FEMALE CALIBRATOR — Calibration block | H20: ='Tool blocks'!E85 -> 1 | I20: =IF(H20=0,"Purchased assembly",IF(T20="Round billet","Ø"&M20&" × "&J20,J20&" × "&K20&" × "&L20)) -> 110 × 95 × 210 | J20: ='Tool blocks'!X85 -> 110 | K20: ='Tool blocks'!Y85 -> 95 | L20: ='Tool blocks'!Z85 -> 210 | M20: ="n.a." -> n.a. | N20: 1000 | O20: 40 | P20: 25 | Q20: n.a. | R20: 2 | S20: 0.33333333 | T20: Rectangular block | U20: Rigid PVC | V20: Illustrative compact profile head; upstream distributor and screw/barrel are separate.
A21: Blow molding | B21: Hollow sphere: Ø100 body; total height 120 with neck; wall ~1 | C21: 100 | D21: 100 | E21: 120 | F21: 1 | G21: FEMALE — Spherical bottle mold half | H21: ='Tool blocks'!E101 -> 2 | I21: =IF(H21=0,"Purchased assembly",IF(T21="Round billet","Ø"&M21&" × "&J21,J21&" × "&K21&" × "&L21)) -> 170 × 190 × 85 | J21: ='Tool blocks'!X101 -> 170 | K21: ='Tool blocks'!Y101 -> 190 | L21: ='Tool blocks'!Z101 -> 85 | M21: ="n.a." -> n.a. | N21: 100 | O21: 100 | P21: 120 | Q21: 100 | R21: 1 | S21: 0.66666667 | T21: Rectangular block | U21: Blow-molding HDPE | V21: Extrusion blow-molding route. Pinch-off, neck and parting detail require final layout.
A22: Blow molding | B22: Hollow sphere: Ø100 body; total height 120 with neck; wall ~1 | C22: 100 | D22: 100 | E22: 120 | F22: 1 | G22: MALE PIN — Blow pin | H22: ='Tool blocks'!E102 -> 1 | I22: =IF(H22=0,"Purchased assembly",IF(T22="Round billet","Ø"&M22&" × "&J22,J22&" × "&K22&" × "&L22)) -> Ø30 × 90 | J22: ='Tool blocks'!Z102 -> 90 | K22: ="n.a." -> n.a. | L22: ="n.a." -> n.a. | M22: ='Tool blocks'!X102 -> 30 | N22: 100 | O22: 100 | P22: 120 | Q22: 100 | R22: 1 | S22: 0.33333333 | T22: Round billet | U22: Blow-molding HDPE | V22: Extrusion blow-molding route. Pinch-off, neck and parting detail require final layout.
A23: Compression molding | B23: Open hemisphere: Ø100 × depth 50; wall 3 | C23: 100 | D23: 100 | E23: 50 | F23: 3 | G23: FEMALE — Outer hemisphere cavity | H23: ='Tool blocks'!E113 -> 1 | I23: =IF(H23=0,"Purchased assembly",IF(T23="Round billet","Ø"&M23&" × "&J23,J23&" × "&K23&" × "&L23)) -> 180 × 180 × 95 | J23: ='Tool blocks'!X113 -> 180 | K23: ='Tool blocks'!Y113 -> 180 | L23: ='Tool blocks'!Z113 -> 95 | M23: ="n.a." -> n.a. | N23: 100 | O23: 100 | P23: 50 | Q23: 100 | R23: 3 | S23: 0.5 | T23: Rectangular block | U23: Glass-filled thermoset SMC | V23: Matched working inserts; press plates, heater cartridges and ejector assembly are additional.
A24: Compression molding | B24: Open hemisphere: Ø100 × depth 50; wall 3 | C24: 100 | D24: 100 | E24: 50 | F24: 3 | G24: MALE — Inner hemisphere core | H24: ='Tool blocks'!E114 -> 1 | I24: =IF(H24=0,"Purchased assembly",IF(T24="Round billet","Ø"&M24&" × "&J24,J24&" × "&K24&" × "&L24)) -> 165 × 165 × 85 | J24: ='Tool blocks'!X114 -> 165 | K24: ='Tool blocks'!Y114 -> 165 | L24: ='Tool blocks'!Z114 -> 85 | M24: ="n.a." -> n.a. | N24: 100 | O24: 100 | P24: 50 | Q24: 100 | R24: 3 | S24: 0.5 | T24: Rectangular block | U24: Glass-filled thermoset SMC | V24: Matched working inserts; press plates, heater cartridges and ejector assembly are additional.
A25: Transfer molding | B25: Block: 60 × 40 × 15; two Ø6 holes | C25: 60 | D25: 40 | E25: 15 | F25: n.a | G25: FEMALE — Cavity half | H25: ='Tool blocks'!E125 -> 2 | I25: =IF(H25=0,"Purchased assembly",IF(T25="Round billet","Ø"&M25&" × "&J25,J25&" × "&K25&" × "&L25)) -> 130 × 110 × 45 | J25: ='Tool blocks'!X125 -> 130 | K25: ='Tool blocks'!Y125 -> 110 | L25: ='Tool blocks'!Z125 -> 45 | M25: ="n.a." -> n.a. | N25: 60 | O25: 40 | P25: 15 | Q25: n.a. | R25: n.a. | S25: 0.33333333 | T25: Rectangular block | U25: Mineral-filled thermoset epoxy | V25: Transfer pot/plunger sizes assumed for one cavity; charge, runner volume and transfer pressure need checking.
A26: Transfer molding | B26: Block: 60 × 40 × 15; two Ø6 holes | C26: 60 | D26: 40 | E26: 15 | F26: n.a | G26: MALE PIN — Hole core pin | H26: ='Tool blocks'!E126 -> 2 | I26: =IF(H26=0,"Purchased assembly",IF(T26="Round billet","Ø"&M26&" × "&J26,J26&" × "&K26&" × "&L26)) -> Ø9 × 43 | J26: ='Tool blocks'!Z126 -> 43 | K26: ="n.a." -> n.a. | L26: ="n.a." -> n.a. | M26: ='Tool blocks'!X126 -> 9 | N26: 60 | O26: 40 | P26: 15 | Q26: n.a. | R26: n.a. | S26: 0.33333333 | T26: Round billet | U26: Mineral-filled thermoset epoxy | V26: Transfer pot/plunger sizes assumed for one cavity; charge, runner volume and transfer pressure need checking.
A27: Transfer molding | B27: Block: 60 × 40 × 15; two Ø6 holes | C27: 60 | D27: 40 | E27: 15 | F27: n.a | G27: FEMALE POT — Transfer pot insert | H27: ='Tool blocks'!E127 -> 1 | I27: =IF(H27=0,"Purchased assembly",IF(T27="Round billet","Ø"&M27&" × "&J27,J27&" × "&K27&" × "&L27)) -> Ø90 × 60 | J27: ='Tool blocks'!Z127 -> 60 | K27: ="n.a." -> n.a. | L27: ="n.a." -> n.a. | M27: ='Tool blocks'!X127 -> 90 | N27: 60 | O27: 40 | P27: 15 | Q27: n.a. | R27: n.a. | S27: 0.16666667 | T27: Round billet | U27: Mineral-filled thermoset epoxy | V27: Transfer pot/plunger sizes assumed for one cavity; charge, runner volume and transfer pressure need checking.
A28: Transfer molding | B28: Block: 60 × 40 × 15; two Ø6 holes | C28: 60 | D28: 40 | E28: 15 | F28: n.a | G28: MALE PLUNGER — Transfer plunger | H28: ='Tool blocks'!E128 -> 1 | I28: =IF(H28=0,"Purchased assembly",IF(T28="Round billet","Ø"&M28&" × "&J28,J28&" × "&K28&" × "&L28)) -> Ø50 × 90 | J28: ='Tool blocks'!Z128 -> 90 | K28: ="n.a." -> n.a. | L28: ="n.a." -> n.a. | M28: ='Tool blocks'!X128 -> 50 | N28: 60 | O28: 40 | P28: 15 | Q28: n.a. | R28: n.a. | S28: 0.16666667 | T28: Round billet | U28: Mineral-filled thermoset epoxy | V28: Transfer pot/plunger sizes assumed for one cavity; charge, runner volume and transfer pressure need checking.
A29: Rotational molding | B29: Hollow sphere: Ø100; wall 3 | C29: 100 | D29: 100 | E29: 100 | F29: 3 | G29: FEMALE SHELL — Machined hemispherical mold shell | H29: ='Tool blocks'!E149 -> 2 | I29: =IF(H29=0,"Purchased assembly",IF(T29="Round billet","Ø"&M29&" × "&J29,J29&" × "&K29&" × "&L29)) -> 150 × 150 × 70 | J29: ='Tool blocks'!X149 -> 150 | K29: ='Tool blocks'!Y149 -> 150 | L29: ='Tool blocks'!Z149 -> 70 | M29: ="n.a." -> n.a. | N29: 100 | O29: 100 | P29: 100 | Q29: 100 | R29: 3 | S29: 1 | T29: Rectangular block | U29: Rotomolding LLDPE | V29: Machined aluminum-shell route chosen so stock can be estimated. Mill the outside to leave an assumed 8 mm shell; keep flange.
A30: Powder metallurgy — press and sinter | B30: Bushing: flange Ø40; body Ø30; bore Ø20; height 25 | C30: 40 | D30: 40 | E30: 25 | F30: n.a | G30: FEMALE DIE — Compaction die body | H30: ='Tool blocks'!E155 -> 1 | I30: =IF(H30=0,"Purchased assembly",IF(T30="Round billet","Ø"&M30&" × "&J30,J30&" × "&K30&" × "&L30)) -> Ø110 × 70 | J30: ='Tool blocks'!Z155 -> 70 | K30: ="n.a." -> n.a. | L30: ="n.a." -> n.a. | M30: ='Tool blocks'!X155 -> 110 | N30: 40 | O30: 40 | P30: 25 | Q30: 40 | R30: Variable | S30: 0.2 | T30: Round billet | U30: Fe-Cu-C powder-metal alloy | V30: Steel development tooling baseline for dimensions. Carbide insert/steel support assemblies require separate interface design.
A31: Powder metallurgy — press and sinter | B31: Bushing: flange Ø40; body Ø30; bore Ø20; height 25 | C31: 40 | D31: 40 | E31: 25 | F31: n.a | G31: MALE PUNCH — Upper annular punch | H31: ='Tool blocks'!E156 -> 1 | I31: =IF(H31=0,"Purchased assembly",IF(T31="Round billet","Ø"&M31&" × "&J31,J31&" × "&K31&" × "&L31)) -> Ø50 × 70 | J31: ='Tool blocks'!Z156 -> 70 | K31: ="n.a." -> n.a. | L31: ="n.a." -> n.a. | M31: ='Tool blocks'!X156 -> 50 | N31: 40 | O31: 40 | P31: 25 | Q31: 40 | R31: Variable | S31: 0.2 | T31: Round billet | U31: Fe-Cu-C powder-metal alloy | V31: Steel development tooling baseline for dimensions. Carbide insert/steel support assemblies require separate interface design.
A32: Powder metallurgy — press and sinter | B32: Bushing: flange Ø40; body Ø30; bore Ø20; height 25 | C32: 40 | D32: 40 | E32: 25 | F32: n.a | G32: MALE PUNCH — Lower inner punch | H32: ='Tool blocks'!E157 -> 1 | I32: =IF(H32=0,"Purchased assembly",IF(T32="Round billet","Ø"&M32&" × "&J32,J32&" × "&K32&" × "&L32)) -> Ø40 × 90 | J32: ='Tool blocks'!Z157 -> 90 | K32: ="n.a." -> n.a. | L32: ="n.a." -> n.a. | M32: ='Tool blocks'!X157 -> 40 | N32: 40 | O32: 40 | P32: 25 | Q32: 40 | R32: Variable | S32: 0.2 | T32: Round billet | U32: Fe-Cu-C powder-metal alloy | V32: Steel development tooling baseline for dimensions. Carbide insert/steel support assemblies require separate interface design.
A33: Powder metallurgy — press and sinter | B33: Bushing: flange Ø40; body Ø30; bore Ø20; height 25 | C33: 40 | D33: 40 | E33: 25 | F33: n.a | G33: MALE PUNCH — Lower outer punch | H33: ='Tool blocks'!E158 -> 1 | I33: =IF(H33=0,"Purchased assembly",IF(T33="Round billet","Ø"&M33&" × "&J33,J33&" × "&K33&" × "&L33)) -> Ø50 × 90 | J33: ='Tool blocks'!Z158 -> 90 | K33: ="n.a." -> n.a. | L33: ="n.a." -> n.a. | M33: ='Tool blocks'!X158 -> 50 | N33: 40 | O33: 40 | P33: 25 | Q33: 40 | R33: Variable | S33: 0.2 | T33: Round billet | U33: Fe-Cu-C powder-metal alloy | V33: Steel development tooling baseline for dimensions. Carbide insert/steel support assemblies require separate interface design.
A34: Powder metallurgy — press and sinter | B34: Bushing: flange Ø40; body Ø30; bore Ø20; height 25 | C34: 40 | D34: 40 | E34: 25 | F34: n.a | G34: MALE CORE — Bore core rod | H34: ='Tool blocks'!E159 -> 1 | I34: =IF(H34=0,"Purchased assembly",IF(T34="Round billet","Ø"&M34&" × "&J34,J34&" × "&K34&" × "&L34)) -> Ø22 × 102 | J34: ='Tool blocks'!Z159 -> 102 | K34: ="n.a." -> n.a. | L34: ="n.a." -> n.a. | M34: ='Tool blocks'!X159 -> 22 | N34: 40 | O34: 40 | P34: 25 | Q34: 40 | R34: Variable | S34: 0.2 | T34: Round billet | U34: Fe-Cu-C powder-metal alloy | V34: Steel development tooling baseline for dimensions. Carbide insert/steel support assemblies require separate interface design.
A35: Metal injection molding — MIM | B35: Clevis: 30 × 15 × 12; sections 3; holes Ø4 | C35: 30 | D35: 15 | E35: 12 | F35: 3 | G35: FEMALE — Cavity insert | H35: ='Tool blocks'!E185 -> 1 | I35: =IF(H35=0,"Purchased assembly",IF(T35="Round billet","Ø"&M35&" × "&J35,J35&" × "&K35&" × "&L35)) -> 95 × 75 × 40 | J35: ='Tool blocks'!X185 -> 95 | K35: ='Tool blocks'!Y185 -> 75 | L35: ='Tool blocks'!Z185 -> 40 | M35: ="n.a." -> n.a. | N35: 30 | O35: 15 | P35: 12 | Q35: n.a. | R35: 3 | S35: 0.25 | T35: Rectangular block | U35: MIM 17-4PH stainless steel | V35: 18% linear tool enlargement is an explicit placeholder for feedstock-specific compensation, not a certified shrinkage.
A36: Metal injection molding — MIM | B36: Clevis: 30 × 15 × 12; sections 3; holes Ø4 | C36: 30 | D36: 15 | E36: 12 | F36: 3 | G36: MALE / CORE SIDE — Core-side insert | H36: ='Tool blocks'!E186 -> 1 | I36: =IF(H36=0,"Purchased assembly",IF(T36="Round billet","Ø"&M36&" × "&J36,J36&" × "&K36&" × "&L36)) -> 95 × 75 × 40 | J36: ='Tool blocks'!X186 -> 95 | K36: ='Tool blocks'!Y186 -> 75 | L36: ='Tool blocks'!Z186 -> 40 | M36: ="n.a." -> n.a. | N36: 30 | O36: 15 | P36: 12 | Q36: n.a. | R36: 3 | S36: 0.25 | T36: Rectangular block | U36: MIM 17-4PH stainless steel | V36: 18% linear tool enlargement is an explicit placeholder for feedstock-specific compensation, not a certified shrinkage.
A37: Metal injection molding — MIM | B37: Clevis: 30 × 15 × 12; sections 3; holes Ø4 | C37: 30 | D37: 15 | E37: 12 | F37: 3 | G37: MALE PIN — Transverse hole core pin | H37: ='Tool blocks'!E187 -> 1 | I37: =IF(H37=0,"Purchased assembly",IF(T37="Round billet","Ø"&M37&" × "&J37,J37&" × "&K37&" × "&L37)) -> Ø7 × 53 | J37: ='Tool blocks'!Z187 -> 53 | K37: ="n.a." -> n.a. | L37: ="n.a." -> n.a. | M37: ='Tool blocks'!X187 -> 7 | N37: 30 | O37: 15 | P37: 12 | Q37: n.a. | R37: 3 | S37: 0.25 | T37: Round billet | U37: MIM 17-4PH stainless steel | V37: 18% linear tool enlargement is an explicit placeholder for feedstock-specific compensation, not a certified shrinkage.
A38: Metal injection molding — MIM | B38: Clevis: 30 × 15 × 12; sections 3; holes Ø4 | C38: 30 | D38: 15 | E38: 12 | F38: 3 | G38: SUPPORT / SLIDE — Core-pin slide carrier | H38: ='Tool blocks'!E188 -> 1 | I38: =IF(H38=0,"Purchased assembly",IF(T38="Round billet","Ø"&M38&" × "&J38,J38&" × "&K38&" × "&L38)) -> 50 × 40 × 40 | J38: ='Tool blocks'!X188 -> 50 | K38: ='Tool blocks'!Y188 -> 40 | L38: ='Tool blocks'!Z188 -> 40 | M38: ="n.a." -> n.a. | N38: 30 | O38: 15 | P38: 12 | Q38: n.a. | R38: 3 | S38: 0.25 | T38: Rectangular block | U38: MIM 17-4PH stainless steel | V38: 18% linear tool enlargement is an explicit placeholder for feedstock-specific compensation, not a certified shrinkage.
A39: Composite molding | B39: Open hemisphere: Ø100 × depth 50; laminate 2 | C39: 100 | D39: 100 | E39: 50 | F39: 2 | G39: FEMALE — Female lay-up mold | H39: ='Tool blocks'!E209 -> 1 | I39: =IF(H39=0,"Purchased assembly",IF(T39="Round billet","Ø"&M39&" × "&J39,J39&" × "&K39&" × "&L39)) -> 190 × 190 × 75 | J39: ='Tool blocks'!X209 -> 190 | K39: ='Tool blocks'!Y209 -> 190 | L39: ='Tool blocks'!Z209 -> 75 | M39: ="n.a." -> n.a. | N39: 100 | O39: 100 | P39: 50 | Q39: 100 | R39: 2 | S39: 1 | T39: Rectangular block | U39: Glass-fiber/epoxy | V39: Machined aluminum one-sided mold selected. RTM would require a separate matched male tool and pressure design.
A40: Pultrusion | B40: Square tube: 40 × 40 × wall 3; length 1000 | C40: 1000 | D40: 40 | E40: 40 | F40: 3 | G40: FEMALE DIE — Split female die block | H40: ='Tool blocks'!E215 -> 2 | I40: =IF(H40=0,"Purchased assembly",IF(T40="Round billet","Ø"&M40&" × "&J40,J40&" × "&K40&" × "&L40)) -> 570 × 110 × 60 | J40: ='Tool blocks'!X215 -> 570 | K40: ='Tool blocks'!Y215 -> 110 | L40: ='Tool blocks'!Z215 -> 60 | M40: ="n.a." -> n.a. | N40: 1000 | O40: 40 | P40: 40 | Q40: n.a. | R40: 3 | S40: 0.66666667 | T40: Rectangular block | U40: Glass-fiber/polyester | V40: Die length is an estimating assumption tied to cure residence time, not finished cut length.
A41: Pultrusion | B41: Square tube: 40 × 40 × wall 3; length 1000 | C41: 1000 | D41: 40 | E41: 40 | F41: 3 | G41: MALE — Internal mandrel | H41: ='Tool blocks'!E216 -> 1 | I41: =IF(H41=0,"Purchased assembly",IF(T41="Round billet","Ø"&M41&" × "&J41,J41&" × "&K41&" × "&L41)) -> 660 × 40 × 40 | J41: ='Tool blocks'!X216 -> 660 | K41: ='Tool blocks'!Y216 -> 40 | L41: ='Tool blocks'!Z216 -> 40 | M41: ="n.a." -> n.a. | N41: 1000 | O41: 40 | P41: 40 | Q41: n.a. | R41: 3 | S41: 0.33333333 | T41: Rectangular block | U41: Glass-fiber/polyester | V41: Die length is an estimating assumption tied to cure residence time, not finished cut length.
A42: Punching / blanking | B42: Flat disc: Ø100 × thickness 2 | C42: 100 | D42: 100 | E42: 2 | F42: 2 | G42: MALE — Blanking punch | H42: ='Tool blocks'!E227 -> 1 | I42: =IF(H42=0,"Purchased assembly",IF(T42="Round billet","Ø"&M42&" × "&J42,J42&" × "&K42&" × "&L42)) -> Ø110 × 70 | J42: ='Tool blocks'!Z227 -> 70 | K42: ="n.a." -> n.a. | L42: ="n.a." -> n.a. | M42: ='Tool blocks'!X227 -> 110 | N42: 100 | O42: 100 | P42: 2 | Q42: 100 | R42: 2 | S42: 0.33333333 | T42: Round billet | U42: DC01 steel | V42: Punch/die clearance not selected; small clearance changes the cutting opening but does not establish structural margins.
...

Sheet Tool blocks
A2: Concrete tooling blocks before machining
A4: Process | B4: Lifetime quantity | C4: Component to manufacture | D4: MALE / FEMALE / other | E4: Pieces per tool set | F4: RAW STOCK TO BUY — mm | G4: Reference part | H4: Finished-part dimensions | I4: Material for this block | J4: Heating / cooling | K4: Stock form | L4: Nominal working envelope L / OD (mm) | M4: Nominal working envelope W (mm) | N4: Nominal working depth / length (mm) | O4: Assumed linear tool enlargement | P4: Side / radial reserve X (mm) | Q4: Side reserve Y (mm) | R4: Backing / mounting reserve (mm) | S4: Machining allowance per face (mm) | T4: Stock rounding increment (mm) | U4: Finished body L / OD (mm) | V4: Finished body W (mm) | W4: Finished body depth / length (mm) | X4: Raw stock L / OD (mm) | Y4: Raw stock W (mm) | Z4: Raw stock depth / length (mm) | AA4: Unique record ID | AB4: What the sizing assumes
A5: Bending | B5: 1–20 | C5: Bending punch | D5: MALE | E5: 1 | F5: =IF(K5="Round billet","Ø"&X5&" × "&Z5,X5&" × "&Y5&" × "&Z5) -> 120 × 40 × 90 | G5: L-bracket | H5: 100 mm bend length; two 50 mm outside legs; sheet 2 mm; inside R3 | I5: ='Quantity grades'!G5 -> 42CrMo4 | J5: Cold process; normally no active cooling | K5: Rectangular block | L5: 100 | M5: 20 | N5: 60 | O5: 0 | P5: 5 | Q5: 5 | R5: 20 | S5: 3 | T5: 5 | U5: =L5*(1+O5)+2*P5 -> 110 | V5: =IF(K5="Round billet","",M5*(1+O5)+2*Q5) -> 30 | W5: =N5*(1+O5)+R5 -> 80 | X5: =ROUNDUP((U5+2*S5)/T5,0)*T5 -> 120 | Y5: =IF(K5="Round billet","",ROUNDUP((V5+2*S5)/T5,0)*T5) -> 40 | Z5: =ROUNDUP((W5+2*S5)/T5,0)*T5 -> 90 | AA5: P01-Q1-C01 | AB5: Illustrative punch-body section, not derived solely from sheet thickness. R3 nose and holder are machined into the envelope.
A6: Bending | B6: 1–20 | C6: V-die | D6: FEMALE DIE | E6: 1 | F6: =IF(K6="Round billet","Ø"&X6&" × "&Z6,X6&" × "&Y6&" × "&Z6) -> 120 × 50 × 45 | G6: L-bracket | H6: 100 mm bend length; two 50 mm outside legs; sheet 2 mm; inside R3 | I6: ='Quantity grades'!G5 -> 42CrMo4 | J6: Cold process; normally no active cooling | K6: Rectangular block | L6: 100 | M6: 16 | N6: 8 | O6: 0 | P6: 5 | Q6: 12 | R6: 27 | S6: 3 | T6: 5 | U6: =L6*(1+O6)+2*P6 -> 110 | V6: =IF(K6="Round billet","",M6*(1+O6)+2*Q6) -> 40 | W6: =N6*(1+O6)+R6 -> 35 | X6: =ROUNDUP((U6+2*S6)/T6,0)*T6 -> 120 | Y6: =IF(K6="Round billet","",ROUNDUP((V6+2*S6)/T6,0)*T6) -> 50 | Z6: =ROUNDUP((W6+2*S6)/T6,0)*T6 -> 45 | AA6: P01-Q1-C02 | AB6: Assumed V-opening 16 mm, 12 mm shoulder reserve each side and 35 mm total die height. Confirm bending load.
A7: Bending | B7: 21–100 | C7: Bending punch | D7: MALE | E7: 1 | F7: =IF(K7="Round billet","Ø"&X7&" × "&Z7,X7&" × "&Y7&" × "&Z7) -> 120 × 40 × 90 | G7: L-bracket | H7: 100 mm bend length; two 50 mm outside legs; sheet 2 mm; inside R3 | I7: ='Quantity grades'!G6 -> 42CrMo4 | J7: Cold process; normally no active cooling | K7: Rectangular block | L7: 100 | M7: 20 | N7: 60 | O7: 0 | P7: 5 | Q7: 5 | R7: 20 | S7: 3 | T7: 5 | U7: =L7*(1+O7)+2*P7 -> 110 | V7: =IF(K7="Round billet","",M7*(1+O7)+2*Q7) -> 30 | W7: =N7*(1+O7)+R7 -> 80 | X7: =ROUNDUP((U7+2*S7)/T7,0)*T7 -> 120 | Y7: =IF(K7="Round billet","",ROUNDUP((V7+2*S7)/T7,0)*T7) -> 40 | Z7: =ROUNDUP((W7+2*S7)/T7,0)*T7 -> 90 | AA7: P01-Q2-C01 | AB7: Illustrative punch-body section, not derived solely from sheet thickness. R3 nose and holder are machined into the envelope.
A8: Bending | B8: 21–100 | C8: V-die | D8: FEMALE DIE | E8: 1 | F8: =IF(K8="Round billet","Ø"&X8&" × "&Z8,X8&" × "&Y8&" × "&Z8) -> 120 × 50 × 45 | G8: L-bracket | H8: 100 mm bend length; two 50 mm outside legs; sheet 2 mm; inside R3 | I8: ='Quantity grades'!G6 -> 42CrMo4 | J8: Cold process; normally no active cooling | K8: Rectangular block | L8: 100 | M8: 16 | N8: 8 | O8: 0 | P8: 5 | Q8: 12 | R8: 27 | S8: 3 | T8: 5 | U8: =L8*(1+O8)+2*P8 -> 110 | V8: =IF(K8="Round billet","",M8*(1+O8)+2*Q8) -> 40 | W8: =N8*(1+O8)+R8 -> 35 | X8: =ROUNDUP((U8+2*S8)/T8,0)*T8 -> 120 | Y8: =IF(K8="Round billet","",ROUNDUP((V8+2*S8)/T8,0)*T8) -> 50 | Z8: =ROUNDUP((W8+2*S8)/T8,0)*T8 -> 45 | AA8: P01-Q2-C02 | AB8: Assumed V-opening 16 mm, 12 mm shoulder reserve each side and 35 mm total die height. Confirm bending load.
A9: Bending | B9: 101–1,000 | C9: Bending punch | D9: MALE | E9: 1 | F9: =IF(K9="Round billet","Ø"&X9&" × "&Z9,X9&" × "&Y9&" × "&Z9) -> 120 × 40 × 90 | G9: L-bracket | H9: 100 mm bend length; two 50 mm outside legs; sheet 2 mm; inside R3 | I9: ='Quantity grades'!G7 -> 42CrMo4 / A2 | J9: Cold process; normally no active cooling | K9: Rectangular block | L9: 100 | M9: 20 | N9: 60 | O9: 0 | P9: 5 | Q9: 5 | R9: 20 | S9: 3 | T9: 5 | U9: =L9*(1+O9)+2*P9 -> 110 | V9: =IF(K9="Round billet","",M9*(1+O9)+2*Q9) -> 30 | W9: =N9*(1+O9)+R9 -> 80 | X9: =ROUNDUP((U9+2*S9)/T9,0)*T9 -> 120 | Y9: =IF(K9="Round billet","",ROUNDUP((V9+2*S9)/T9,0)*T9) -> 40 | Z9: =ROUNDUP((W9+2*S9)/T9,0)*T9 -> 90 | AA9: P01-Q3-C01 | AB9: Illustrative punch-body section, not derived solely from sheet thickness. R3 nose and holder are machined into the envelope.
A10: Bending | B10: 101–1,000 | C10: V-die | D10: FEMALE DIE | E10: 1 | F10: =IF(K10="Round billet","Ø"&X10&" × "&Z10,X10&" × "&Y10&" × "&Z10) -> 120 × 50 × 45 | G10: L-bracket | H10: 100 mm bend length; two 50 mm outside legs; sheet 2 mm; inside R3 | I10: ='Quantity grades'!G7 -> 42CrMo4 / A2 | J10: Cold process; normally no active cooling | K10: Rectangular block | L10: 100 | M10: 16 | N10: 8 | O10: 0 | P10: 5 | Q10: 12 | R10: 27 | S10: 3 | T10: 5 | U10: =L10*(1+O10)+2*P10 -> 110 | V10: =IF(K10="Round billet","",M10*(1+O10)+2*Q10) -> 40 | W10: =N10*(1+O10)+R10 -> 35 | X10: =ROUNDUP((U10+2*S10)/T10,0)*T10 -> 120 | Y10: =IF(K10="Round billet","",ROUNDUP((V10+2*S10)/T10,0)*T10) -> 50 | Z10: =ROUNDUP((W10+2*S10)/T10,0)*T10 -> 45 | AA10: P01-Q3-C02 | AB10: Assumed V-opening 16 mm, 12 mm shoulder reserve each side and 35 mm total die height. Confirm bending load.
A11: Bending | B11: 1,001–10,000 | C11: Bending punch | D11: MALE | E11: 1 | F11: =IF(K11="Round billet","Ø"&X11&" × "&Z11,X11&" × "&Y11&" × "&Z11) -> 120 × 40 × 90 | G11: L-bracket | H11: 100 mm bend length; two 50 mm outside legs; sheet 2 mm; inside R3 | I11: ='Quantity grades'!G8 -> 42CrMo4 / A2 | J11: Cold process; normally no active cooling | K11: Rectangular block | L11: 100 | M11: 20 | N11: 60 | O11: 0 | P11: 5 | Q11: 5 | R11: 20 | S11: 3 | T11: 5 | U11: =L11*(1+O11)+2*P11 -> 110 | V11: =IF(K11="Round billet","",M11*(1+O11)+2*Q11) -> 30 | W11: =N11*(1+O11)+R11 -> 80 | X11: =ROUNDUP((U11+2*S11)/T11,0)*T11 -> 120 | Y11: =IF(K11="Round billet","",ROUNDUP((V11+2*S11)/T11,0)*T11) -> 40 | Z11: =ROUNDUP((W11+2*S11)/T11,0)*T11 -> 90 | AA11: P01-Q4-C01 | AB11: Illustrative punch-body section, not derived solely from sheet thickness. R3 nose and holder are machined into the envelope.
A12: Bending | B12: 1,001–10,000 | C12: V-die | D12: FEMALE DIE | E12: 1 | F12: =IF(K12="Round billet","Ø"&X12&" × "&Z12,X12&" × "&Y12&" × "&Z12) -> 120 × 50 × 45 | G12: L-bracket | H12: 100 mm bend length; two 50 mm outside legs; sheet 2 mm; inside R3 | I12: ='Quantity grades'!G8 -> 42CrMo4 / A2 | J12: Cold process; normally no active cooling | K12: Rectangular block | L12: 100 | M12: 16 | N12: 8 | O12: 0 | P12: 5 | Q12: 12 | R12: 27 | S12: 3 | T12: 5 | U12: =L12*(1+O12)+2*P12 -> 110 | V12: =IF(K12="Round billet","",M12*(1+O12)+2*Q12) -> 40 | W12: =N12*(1+O12)+R12 -> 35 | X12: =ROUNDUP((U12+2*S12)/T12,0)*T12 -> 120 | Y12: =IF(K12="Round billet","",ROUNDUP((V12+2*S12)/T12,0)*T12) -> 50 | Z12: =ROUNDUP((W12+2*S12)/T12,0)*T12 -> 45 | AA12: P01-Q4-C02 | AB12: Assumed V-opening 16 mm, 12 mm shoulder reserve each side and 35 mm total die height. Confirm bending load.
A13: Bending | B13: 10,001–100,000 | C13: Bending punch | D13: MALE | E13: 1 | F13: =IF(K13="Round billet","Ø"&X13&" × "&Z13,X13&" × "&Y13&" × "&Z13) -> 120 × 40 × 90 | G13: L-bracket | H13: 100 mm bend length; two 50 mm outside legs; sheet 2 mm; inside R3 | I13: ='Quantity grades'!G9 -> A2; D2 where wear dominates | J13: Cold process; normally no active cooling | K13: Rectangular block | L13: 100 | M13: 20 | N13: 60 | O13: 0 | P13: 5 | Q13: 5 | R13: 20 | S13: 3 | T13: 5 | U13: =L13*(1+O13)+2*P13 -> 110 | V13: =IF(K13="Round billet","",M13*(1+O13)+2*Q13) -> 30 | W13: =N13*(1+O13)+R13 -> 80 | X13: =ROUNDUP((U13+2*S13)/T13,0)*T13 -> 120 | Y13: =IF(K13="Round billet","",ROUNDUP((V13+2*S13)/T13,0)*T13) -> 40 | Z13: =ROUNDUP((W13+2*S13)/T13,0)*T13 -> 90 | AA13: P01-Q5-C01 | AB13: Illustrative punch-body section, not derived solely from sheet thickness. R3 nose and holder are machined into the envelope.
A14: Bending | B14: 10,001–100,000 | C14: V-die | D14: FEMALE DIE | E14: 1 | F14: =IF(K14="Round billet","Ø"&X14&" × "&Z14,X14&" × "&Y14&" × "&Z14) -> 120 × 50 × 45 | G14: L-bracket | H14: 100 mm bend length; two 50 mm outside legs; sheet 2 mm; inside R3 | I14: ='Quantity grades'!G9 -> A2; D2 where wear dominates | J14: Cold process; normally no active cooling | K14: Rectangular block | L14: 100 | M14: 16 | N14: 8 | O14: 0 | P14: 5 | Q14: 12 | R14: 27 | S14: 3 | T14: 5 | U14: =L14*(1+O14)+2*P14 -> 110 | V14: =IF(K14="Round billet","",M14*(1+O14)+2*Q14) -> 40 | W14: =N14*(1+O14)+R14 -> 35 | X14: =ROUNDUP((U14+2*S14)/T14,0)*T14 -> 120 | Y14: =IF(K14="Round billet","",ROUNDUP((V14+2*S14)/T14,0)*T14) -> 50 | Z14: =ROUNDUP((W14+2*S14)/T14,0)*T14 -> 45 | AA14: P01-Q5-C02 | AB14: Assumed V-opening 16 mm, 12 mm shoulder reserve each side and 35 mm total die height. Confirm bending load.
A15: Bending | B15: Above 100,000 | C15: Bending punch | D15: MALE | E15: 1 | F15: =IF(K15="Round billet","Ø"&X15&" × "&Z15,X15&" × "&Y15&" × "&Z15) -> 120 × 40 × 90 | G15: L-bracket | H15: 100 mm bend length; two 50 mm outside legs; sheet 2 mm; inside R3 | I15: ='Quantity grades'!G10 -> A2 / premium cold-work steel | J15: Cold process; normally no active cooling | K15: Rectangular block | L15: 100 | M15: 20 | N15: 60 | O15: 0 | P15: 5 | Q15: 5 | R15: 20 | S15: 3 | T15: 5 | U15: =L15*(1+O15)+2*P15 -> 110 | V15: =IF(K15="Round billet","",M15*(1+O15)+2*Q15) -> 30 | W15: =N15*(1+O15)+R15 -> 80 | X15: =ROUNDUP((U15+2*S15)/T15,0)*T15 -> 120 | Y15: =IF(K15="Round billet","",ROUNDUP((V15+2*S15)/T15,0)*T15) -> 40 | Z15: =ROUNDUP((W15+2*S15)/T15,0)*T15 -> 90 | AA15: P01-Q6-C01 | AB15: Illustrative punch-body section, not derived solely from sheet thickness. R3 nose and holder are machined into the envelope.
A16: Bending | B16: Above 100,000 | C16: V-die | D16: FEMALE DIE | E16: 1 | F16: =IF(K16="Round billet","Ø"&X16&" × "&Z16,X16&" × "&Y16&" × "&Z16) -> 120 × 50 × 45 | G16: L-bracket | H16: 100 mm bend length; two 50 mm outside legs; sheet 2 mm; inside R3 | I16: ='Quantity grades'!G10 -> A2 / premium cold-work steel | J16: Cold process; normally no active cooling | K16: Rectangular block | L16: 100 | M16: 16 | N16: 8 | O16: 0 | P16: 5 | Q16: 12 | R16: 27 | S16: 3 | T16: 5 | U16: =L16*(1+O16)+2*P16 -> 110 | V16: =IF(K16="Round billet","",M16*(1+O16)+2*Q16) -> 40 | W16: =N16*(1+O16)+R16 -> 35 | X16: =ROUNDUP((U16+2*S16)/T16,0)*T16 -> 120 | Y16: =IF(K16="Round billet","",ROUNDUP((V16+2*S16)/T16,0)*T16) -> 50 | Z16: =ROUNDUP((W16+2*S16)/T16,0)*T16 -> 45 | AA16: P01-Q6-C02 | AB16: Assumed V-opening 16 mm, 12 mm shoulder reserve each side and 35 mm total die height. Confirm bending load.
A17: Metal extrusion | B17: 1–20 | C17: Profile die disk | D17: FEMALE DIE | E17: 1 | F17: =IF(K17="Round billet","Ø"&X17&" × "&Z17,X17&" × "&Y17&" × "&Z17) -> Ø190 × 70 | G17: Hollow square extrusion | H17: 40 × 40 mm outside; wall 3 mm; cut length 1,000 mm | I17: ='Quantity grades'!G11 -> H13 | J17: Hot die/billet; nitrided working surfaces; process-specific temperature control | K17: Round billet | L17: 57 | M17: 57 | N17: 20 | O17: 0 | P17: 61.5 | Q17: 61.5 | R17: 40 | S17: 3 | T17: 5 | U17: =L17*(1+O17)+2*P17 -> 180 | V17: =IF(K17="Round billet","",M17*(1+O17)+2*Q17) | W17: =N17*(1+O17)+R17 -> 60 | X17: =ROUNDUP((U17+2*S17)/T17,0)*T17 -> 190 | Y17: =IF(K17="Round billet","",ROUNDUP((V17+2*S17)/T17,0)*T17) | Z17: =ROUNDUP((W17+2*S17)/T17,0)*T17 -> 70 | AA17: P02-Q1-C01 | AB17: 57 mm circumscribed profile envelope. Assumed finished die OD180 × 60 mm; pressure and bearing design unvalidated.
A18: Metal extrusion | B18: 1–20 | C18: Bridge plate with integral mandrel | D18: MALE / BRIDGE | E18: 1 | F18: =IF(K18="Round billet","Ø"&X18&" × "&Z18,X18&" × "&Y18&" × "&Z18) -> Ø190 × 70 | G18: Hollow square extrusion | H18: 40 × 40 mm outside; wall 3 mm; cut length 1,000 mm | I18: ='Quantity grades'!G11 -> H13 | J18: Hot die/billet; nitrided working surfaces; process-specific temperature control | K18: Round billet | L18: 57 | M18: 57 | N18: 20 | O18: 0 | P18: 61.5 | Q18: 61.5 | R18: 40 | S18: 3 | T18: 5 | U18: =L18*(1+O18)+2*P18 -> 180 | V18: =IF(K18="Round billet","",M18*(1+O18)+2*Q18) | W18: =N18*(1+O18)+R18 -> 60 | X18: =ROUNDUP((U18+2*S18)/T18,0)*T18 -> 190 | Y18: =IF(K18="Round billet","",ROUNDUP((V18+2*S18)/T18,0)*T18) | Z18: =ROUNDUP((W18+2*S18)/T18,0)*T18 -> 70 | AA18: P02-Q1-C02 | AB18: Hollow profile requires bridge-supported internal mandrel; bridges/ports must be sized for extrusion pressure.
A19: Metal extrusion | B19: 1–20 | C19: Die backer | D19: SUPPORT | E19: 1 | F19: =IF(K19="Round billet","Ø"&X19&" × "&Z19,X19&" × "&Y19&" × "&Z19) -> Ø190 × 50 | G19: Hollow square extrusion | H19: 40 × 40 mm outside; wall 3 mm; cut length 1,000 mm | I19: 42CrMo4 or supplier-rated backing grade | J19: Hot die/billet; nitrided working surfaces; process-specific temperature control | K19: Round billet | L19: 180 | M19: 180 | N19: 40 | O19: 0 | P19: 0 | Q19: 0 | R19: 0 | S19: 3 | T19: 5 | U19: =L19*(1+O19)+2*P19 -> 180 | V19: =IF(K19="Round billet","",M19*(1+O19)+2*Q19) | W19: =N19*(1+O19)+R19 -> 40 | X19: =ROUNDUP((U19+2*S19)/T19,0)*T19 -> 190 | Y19: =IF(K19="Round billet","",ROUNDUP((V19+2*S19)/T19,0)*T19) | Z19: =ROUNDUP((W19+2*S19)/T19,0)*T19 -> 50 | AA19: P02-Q1-C03 | AB19: Assumed finished Ø180 × 40 mm; actual support design required.
A20: Metal extrusion | B20: 21–100 | C20: Profile die disk | D20: FEMALE DIE | E20: 1 | F20: =IF(K20="Round billet","Ø"&X20&" × "&Z20,X20&" × "&Y20&" × "&Z20) -> Ø190 × 70 | G20: Hollow square extrusion | H20: 40 × 40 mm outside; wall 3 mm; cut length 1,000 mm | I20: ='Quantity grades'!G12 -> H13 | J20: Hot die/billet; nitrided working surfaces; process-specific temperature control | K20: Round billet | L20: 57 | M20: 57 | N20: 20 | O20: 0 | P20: 61.5 | Q20: 61.5 | R20: 40 | S20: 3 | T20: 5 | U20: =L20*(1+O20)+2*P20 -> 180 | V20: =IF(K20="Round billet","",M20*(1+O20)+2*Q20) | W20: =N20*(1+O20)+R20 -> 60 | X20: =ROUNDUP((U20+2*S20)/T20,0)*T20 -> 190 | Y20: =IF(K20="Round billet","",ROUNDUP((V20+2*S20)/T20,0)*T20) | Z20: =ROUNDUP((W20+2*S20)/T20,0)*T20 -> 70 | AA20: P02-Q2-C01 | AB20: 57 mm circumscribed profile envelope. Assumed finished die OD180 × 60 mm; pressure and bearing design unvalidated.
A21: Metal extrusion | B21: 21–100 | C21: Bridge plate with integral mandrel | D21: MALE / BRIDGE | E21: 1 | F21: =IF(K21="Round billet","Ø"&X21&" × "&Z21,X21&" × "&Y21&" × "&Z21) -> Ø190 × 70 | G21: Hollow square extrusion | H21: 40 × 40 mm outside; wall 3 mm; cut length 1,000 mm | I21: ='Quantity grades'!G12 -> H13 | J21: Hot die/billet; nitrided working surfaces; process-specific temperature control | K21: Round billet | L21: 57 | M21: 57 | N21: 20 | O21: 0 | P21: 61.5 | Q21: 61.5 | R21: 40 | S21: 3 | T21: 5 | U21: =L21*(1+O21)+2*P21 -> 180 | V21: =IF(K21="Round billet","",M21*(1+O21)+2*Q21) | W21: =N21*(1+O21)+R21 -> 60 | X21: =ROUNDUP((U21+2*S21)/T21,0)*T21 -> 190 | Y21: =IF(K21="Round billet","",ROUNDUP((V21+2*S21)/T21,0)*T21) | Z21: =ROUNDUP((W21+2*S21)/T21,0)*T21 -> 70 | AA21: P02-Q2-C02 | AB21: Hollow profile requires bridge-supported internal mandrel; bridges/ports must be sized for extrusion pressure.
A22: Metal extrusion | B22: 21–100 | C22: Die backer | D22: SUPPORT | E22: 1 | F22: =IF(K22="Round billet","Ø"&X22&" × "&Z22,X22&" × "&Y22&" × "&Z22) -> Ø190 × 50 | G22: Hollow square extrusion | H22: 40 × 40 mm outside; wall 3 mm; cut length 1,000 mm | I22: 42CrMo4 or supplier-rated backing grade | J22: Hot die/billet; nitrided working surfaces; process-specific temperature control | K22: Round billet | L22: 180 | M22: 180 | N22: 40 | O22: 0 | P22: 0 | Q22: 0 | R22: 0 | S22: 3 | T22: 5 | U22: =L22*(1+O22)+2*P22 -> 180 | V22: =IF(K22="Round billet","",M22*(1+O22)+2*Q22) | W22: =N22*(1+O22)+R22 -> 40 | X22: =ROUNDUP((U22+2*S22)/T22,0)*T22 -> 190 | Y22: =IF(K22="Round billet","",ROUNDUP((V22+2*S22)/T22,0)*T22) | Z22: =ROUNDUP((W22+2*S22)/T22,0)*T22 -> 50 | AA22: P02-Q2-C03 | AB22: Assumed finished Ø180 × 40 mm; actual support design required.
A23: Metal extrusion | B23: 101–1,000 | C23: Profile die disk | D23: FEMALE DIE | E23: 1 | F23: =IF(K23="Round billet","Ø"&X23&" × "&Z23,X23&" × "&Y23&" × "&Z23) -> Ø190 × 70 | G23: Hollow square extrusion | H23: 40 × 40 mm outside; wall 3 mm; cut length 1,000 mm | I23: ='Quantity grades'!G13 -> H13 | J23: Hot die/billet; nitrided working surfaces; process-specific temperature control | K23: Round billet | L23: 57 | M23: 57 | N23: 20 | O23: 0 | P23: 61.5 | Q23: 61.5 | R23: 40 | S23: 3 | T23: 5 | U23: =L23*(1+O23)+2*P23 -> 180 | V23: =IF(K23="Round billet","",M23*(1+O23)+2*Q23) | W23: =N23*(1+O23)+R23 -> 60 | X23: =ROUNDUP((U23+2*S23)/T23,0)*T23 -> 190 | Y23: =IF(K23="Round billet","",ROUNDUP((V23+2*S23)/T23,0)*T23) | Z23: =ROUNDUP((W23+2*S23)/T23,0)*T23 -> 70 | AA23: P02-Q3-C01 | AB23: 57 mm circumscribed profile envelope. Assumed finished die OD180 × 60 mm; pressure and bearing design unvalidated.
A24: Metal extrusion | B24: 101–1,000 | C24: Bridge plate with integral mandrel | D24: MALE / BRIDGE | E24: 1 | F24: =IF(K24="Round billet","Ø"&X24&" × "&Z24,X24&" × "&Y24&" × "&Z24) -> Ø190 × 70 | G24: Hollow square extrusion | H24: 40 × 40 mm outside; wall 3 mm; cut length 1,000 mm | I24: ='Quantity grades'!G13 -> H13 | J24: Hot die/billet; nitrided working surfaces; process-specific temperature control | K24: Round billet | L24: 57 | M24: 57 | N24: 20 | O24: 0 | P24: 61.5 | Q24: 61.5 | R24: 40 | S24: 3 | T24: 5 | U24: =L24*(1+O24)+2*P24 -> 180 | V24: =IF(K24="Round billet","",M24*(1+O24)+2*Q24) | W24: =N24*(1+O24)+R24 -> 60 | X24: =ROUNDUP((U24+2*S24)/T24,0)*T24 -> 190 | Y24: =IF(K24="Round billet","",ROUNDUP((V24+2*S24)/T24,0)*T24) | Z24: =ROUNDUP((W24+2*S24)/T24,0)*T24 -> 70 | AA24: P02-Q3-C02 | AB24: Hollow profile requires bridge-supported internal mandrel; bridges/ports must be sized for extrusion pressure.
A25: Metal extrusion | B25: 101–1,000 | C25: Die backer | D25: SUPPORT | E25: 1 | F25: =IF(K25="Round billet","Ø"&X25&" × "&Z25,X25&" × "&Y25&" × "&Z25) -> Ø190 × 50 | G25: Hollow square extrusion | H25: 40 × 40 mm outside; wall 3 mm; cut length 1,000 mm | I25: 42CrMo4 or supplier-rated backing grade | J25: Hot die/billet; nitrided working surfaces; process-specific temperature control | K25: Round billet | L25: 180 | M25: 180 | N25: 40 | O25: 0 | P25: 0 | Q25: 0 | R25: 0 | S25: 3 | T25: 5 | U25: =L25*(1+O25)+2*P25 -> 180 | V25: =IF(K25="Round billet","",M25*(1+O25)+2*Q25) | W25: =N25*(1+O25)+R25 -> 40 | X25: =ROUNDUP((U25+2*S25)/T25,0)*T25 -> 190 | Y25: =IF(K25="Round billet","",ROUNDUP((V25+2*S25)/T25,0)*T25) | Z25: =ROUNDUP((W25+2*S25)/T25,0)*T25 -> 50 | AA25: P02-Q3-C03 | AB25: Assumed finished Ø180 × 40 mm; actual support design required.
A26: Metal extrusion | B26: 1,001–10,000 | C26: Profile die disk | D26: FEMALE DIE | E26: 1 | F26: =IF(K26="Round billet","Ø"&X26&" × "&Z26,X26&" × "&Y26&" × "&Z26) -> Ø190 × 70 | G26: Hollow square extrusion | H26: 40 × 40 mm outside; wall 3 mm; cut length 1,000 mm | I26: ='Quantity grades'!G14 -> H13 | J26: Hot die/billet; nitrided working surfaces; process-specific temperature control | K26: Round billet | L26: 57 | M26: 57 | N26: 20 | O26: 0 | P26: 61.5 | Q26: 61.5 | R26: 40 | S26: 3 | T26: 5 | U26: =L26*(1+O26)+2*P26 -> 180 | V26: =IF(K26="Round billet","",M26*(1+O26)+2*Q26) | W26: =N26*(1+O26)+R26 -> 60 | X26: =ROUNDUP((U26+2*S26)/T26,0)*T26 -> 190 | Y26: =IF(K26="Round billet","",ROUNDUP((V26+2*S26)/T26,0)*T26) | Z26: =ROUNDUP((W26+2*S26)/T26,0)*T26 -> 70 | AA26: P02-Q4-C01 | AB26: 57 mm circumscribed profile envelope. Assumed finished die OD180 × 60 mm; pressure and bearing design unvalidated.
A27: Metal extrusion | B27: 1,001–10,000 | C27: Bridge plate with integral mandrel | D27: MALE / BRIDGE | E27: 1 | F27: =IF(K27="Round billet","Ø"&X27&" × "&Z27,X27&" × "&Y27&" × "&Z27) -> Ø190 × 70 | G27: Hollow square extrusion | H27: 40 × 40 mm outside; wall 3 mm; cut length 1,000 mm | I27: ='Quantity grades'!G14 -> H13 | J27: Hot die/billet; nitrided working surfaces; process-specific temperature control | K27: Round billet | L27: 57 | M27: 57 | N27: 20 | O27: 0 | P27: 61.5 | Q27: 61.5 | R27: 40 | S27: 3 | T27: 5 | U27: =L27*(1+O27)+2*P27 -> 180 | V27: =IF(K27="Round billet","",M27*(1+O27)+2*Q27) | W27: =N27*(1+O27)+R27 -> 60 | X27: =ROUNDUP((U27+2*S27)/T27,0)*T27 -> 190 | Y27: =IF(K27="Round billet","",ROUNDUP((V27+2*S27)/T27,0)*T27) | Z27: =ROUNDUP((W27+2*S27)/T27,0)*T27 -> 70 | AA27: P02-Q4-C02 | AB27: Hollow profile requires bridge-supported internal mandrel; bridges/ports must be sized for extrusion pressure.
A28: Metal extrusion | B28: 1,001–10,000 | C28: Die backer | D28: SUPPORT | E28: 1 | F28: =IF(K28="Round billet","Ø"&X28&" × "&Z28,X28&" × "&Y28&" × "&Z28) -> Ø190 × 50 | G28: Hollow square extrusion | H28: 40 × 40 mm outside; wall 3 mm; cut length 1,000 mm | I28: 42CrMo4 or supplier-rated backing grade | J28: Hot die/billet; nitrided working surfaces; process-specific temperature control | K28: Round billet | L28: 180 | M28: 180 | N28: 40 | O28: 0 | P28: 0 | Q28: 0 | R28: 0 | S28: 3 | T28: 5 | U28: =L28*(1+O28)+2*P28 -> 180 | V28: =IF(K28="Round billet","",M28*(1+O28)+2*Q28) | W28: =N28*(1+O28)+R28 -> 40 | X28: =ROUNDUP((U28+2*S28)/T28,0)*T28 -> 190 | Y28: =IF(K28="Round billet","",ROUNDUP((V28+2*S28)/T28,0)*T28) | Z28: =ROUNDUP((W28+2*S28)/T28,0)*T28 -> 50 | AA28: P02-Q4-C03 | AB28: Assumed finished Ø180 × 40 mm; actual support design required.
A29: Metal extrusion | B29: 10,001–100,000 | C29: Profile die disk | D29: FEMALE DIE | E29: 1 | F29: =IF(K29="Round billet","Ø"&X29&" × "&Z29,X29&" × "&Y29&" × "&Z29) -> Ø190 × 70 | G29: Hollow square extrusion | H29: 40 × 40 mm outside; wall 3 mm; cut length 1,000 mm | I29: ='Quantity grades'!G15 -> H13 / H13 ESR | J29: Hot die/billet; nitrided working surfaces; process-specific temperature control | K29: Round billet | L29: 57 | M29: 57 | N29: 20 | O29: 0 | P29: 61.5 | Q29: 61.5 | R29: 40 | S29: 3 | T29: 5 | U29: =L29*(1+O29)+2*P29 -> 180 | V29: =IF(K29="Round billet","",M29*(1+O29)+2*Q29) | W29: =N29*(1+O29)+R29 -> 60 | X29: =ROUNDUP((U29+2*S29)/T29,0)*T29 -> 190 | Y29: =IF(K29="Round billet","",ROUNDUP((V29+2*S29)/T29,0)*T29) | Z29: =ROUNDUP((W29+2*S29)/T29,0)*T29 -> 70 | AA29: P02-Q5-C01 | AB29: 57 mm circumscribed profile envelope. Assumed finished die OD180 × 60 mm; pressure and bearing design unvalidated.
A30: Metal extrusion | B30: 10,001–100,000 | C30: Bridge plate with integral mandrel | D30: MALE / BRIDGE | E30: 1 | F30: =IF(K30="Round billet","Ø"&X30&" × "&Z30,X30&" × "&Y30&" × "&Z30) -> Ø190 × 70 | G30: Hollow square extrusion | H30: 40 × 40 mm outside; wall 3 mm; cut length 1,000 mm | I30: ='Quantity grades'!G15 -> H13 / H13 ESR | J30: Hot die/billet; nitrided working surfaces; process-specific temperature control | K30: Round billet | L30: 57 | M30: 57 | N30: 20 | O30: 0 | P30: 61.5 | Q30: 61.5 | R30: 40 | S30: 3 | T30: 5 | U30: =L30*(1+O30)+2*P30 -> 180 | V30: =IF(K30="Round billet","",M30*(1+O30)+2*Q30) | W30: =N30*(1+O30)+R30 -> 60 | X30: =ROUNDUP((U30+2*S30)/T30,0)*T30 -> 190 | Y30: =IF(K30="Round billet","",ROUNDUP((V30+2*S30)/T30,0)*T30) | Z30: =ROUNDUP((W30+2*S30)/T30,0)*T30 -> 70 | AA30: P02-Q5-C02 | AB30: Hollow profile requires bridge-supported internal mandrel; bridges/ports must be sized for extrusion pressure.
A31: Metal extrusion | B31: 10,001–100,000 | C31: Die backer | D31: SUPPORT | E31: 1 | F31: =IF(K31="Round billet","Ø"&X31&" × "&Z31,X31&" × "&Y31&" × "&Z31) -> Ø190 × 50 | G31: Hollow square extrusion | H31: 40 × 40 mm outside; wall 3 mm; cut length 1,000 mm | I31: 42CrMo4 or supplier-rated backing grade | J31: Hot die/billet; nitrided working surfaces; process-specific temperature control | K31: Round billet | L31: 180 | M31: 180 | N31: 40 | O31: 0 | P31: 0 | Q31: 0 | R31: 0 | S31: 3 | T31: 5 | U31: =L31*(1+O31)+2*P31 -> 180 | V31: =IF(K31="Round billet","",M31*(1+O31)+2*Q31) | W31: =N31*(1+O31)+R31 -> 40 | X31: =ROUNDUP((U31+2*S31)/T31,0)*T31 -> 190 | Y31: =IF(K31="Round billet","",ROUNDUP((V31+2*S31)/T31,0)*T31) | Z31: =ROUNDUP((W31+2*S31)/T31,0)*T31 -> 50 | AA31: P02-Q5-C03 | AB31: Assumed finished Ø180 × 40 mm; actual support design required.
A32: Metal extrusion | B32: Above 100,000 | C32: Profile die disk | D32: FEMALE DIE | E32: 1 | F32: =IF(K32="Round billet","Ø"&X32&" × "&Z32,X32&" × "&Y32&" × "&Z32) -> Ø190 × 70 | G32: Hollow square extrusion | H32: 40 × 40 mm outside; wall 3 mm; cut length 1,000 mm | I32: ='Quantity grades'!G16 -> H13 ESR / specialist hot-work steel | J32: Hot die/billet; nitrided working surfaces; process-specific temperature control | K32: Round billet | L32: 57 | M32: 57 | N32: 20 | O32: 0 | P32: 61.5 | Q32: 61.5 | R32: 40 | S32: 3 | T32: 5 | U32: =L32*(1+O32)+2*P32 -> 180 | V32: =IF(K32="Round billet","",M32*(1+O32)+2*Q32) | W32: =N32*(1+O32)+R32 -> 60 | X32: =ROUNDUP((U32+2*S32)/T32,0)*T32 -> 190 | Y32: =IF(K32="Round billet","",ROUNDUP((V32+2*S32)/T32,0)*T32) | Z32: =ROUNDUP((W32+2*S32)/T32,0)*T32 -> 70 | AA32: P02-Q6-C01 | AB32: 57 mm circumscribed profile envelope. Assumed finished die OD180 × 60 mm; pressure and bearing design unvalidated.
A33: Metal extrusion | B33: Above 100,000 | C33: Bridge plate with integral mandrel | D33: MALE / BRIDGE | E33: 1 | F33: =IF(K33="Round billet","Ø"&X33&" × "&Z33,X33&" × "&Y33&" × "&Z33) -> Ø190 × 70 | G33: Hollow square extrusion | H33: 40 × 40 mm outside; wall 3 mm; cut length 1,000 mm | I33: ='Quantity grades'!G16 -> H13 ESR / specialist hot-work steel | J33: Hot die/billet; nitrided working surfaces; process-specific temperature control | K33: Round billet | L33: 57 | M33: 57 | N33: 20 | O33: 0 | P33: 61.5 | Q33: 61.5 | R33: 40 | S33: 3 | T33: 5 | U33: =L33*(1+O33)+2*P33 -> 180 | V33: =IF(K33="Round billet","",M33*(1+O33)+2*Q33) | W33: =N33*(1+O33)+R33 -> 60 | X33: =ROUNDUP((U33+2*S33)/T33,0)*T33 -> 190 | Y33: =IF(K33="Round billet","",ROUNDUP((V33+2*S33)/T33,0)*T33) | Z33: =ROUNDUP((W33+2*S33)/T33,0)*T33 -> 70 | AA33: P02-Q6-C02 | AB33: Hollow profile requires bridge-supported internal mandrel; bridges/ports must be sized for extrusion pressure.
A34: Metal extrusion | B34: Above 100,000 | C34: Die backer | D34: SUPPORT | E34: 1 | F34: =IF(K34="Round billet","Ø"&X34&" × "&Z34,X34&" × "&Y34&" × "&Z34) -> Ø190 × 50 | G34: Hollow square extrusion | H34: 40 × 40 mm outside; wall 3 mm; cut length 1,000 mm | I34: 42CrMo4 or supplier-rated backing grade | J34: Hot die/billet; nitrided working surfaces; process-specific temperature control | K34: Round billet | L34: 180 | M34: 180 | N34: 40 | O34: 0 | P34: 0 | Q34: 0 | R34: 0 | S34: 3 | T34: 5 | U34: =L34*(1+O34)+2*P34 -> 180 | V34: =IF(K34="Round billet","",M34*(1+O34)+2*Q34) | W34: =N34*(1+O34)+R34 -> 40 | X34: =ROUNDUP((U34+2*S34)/T34,0)*T34 -> 190 | Y34: =IF(K34="Round billet","",ROUNDUP((V34+2*S34)/T34,0)*T34) | Z34: =ROUNDUP((W34+2*S34)/T34,0)*T34 -> 50 | AA34: P02-Q6-C03 | AB34: Assumed finished Ø180 × 40 mm; actual support design required.
A35: Die casting | B35: 1–20 | C35: Outer hemisphere cavity | D35: FEMALE | E35: 1 | F35: =IF(K35="Round billet","Ø"&X35&" × "&Z35,X35&" × "&Y35&" × "&Z35) -> 190 × 190 × 100 | G35: Hemispherical shell | H35: Outside Ø100 mm; depth 50 mm; nominal wall 3 mm; open equator | I35: ='Quantity grades'!G17 -> H13 | J35: Die preheat; internal temperature-control circuits and external spray | K35: Rectangular block | L35: 100 | M35: 100 | N35: 50 | O35: 0.006 | P35: 40 | Q35: 40 | R35: 40 | S35: 3 | T35: 5 | U35: =L35*(1+O35)+2*P35 -> 180.6 | V35: =IF(K35="Round billet","",M35*(1+O35)+2*Q35) -> 180.6 | W35: =N35*(1+O35)+R35 -> 90.3 | X35: =ROUNDUP((U35+2*S35)/T35,0)*T35 -> 190 | Y35: =IF(K35="Round billet","",ROUNDUP((V35+2*S35)/T35,0)*T35) -> 190 | Z35: =ROUNDUP((W35+2*S35)/T35,0)*T35 -> 100 | AA35: P03-Q1-C01 | AB35: 40 mm peripheral reserve for support and local feed/cooling layout; exact features not yet laid out.
A36: Die casting | B36: 1–20 | C36: Inner hemisphere core | D36: MALE | E36: 1 | F36: =IF(K36="Round billet","Ø"&X36&" × "&Z36,X36&" × "&Y36&" × "&Z36) -> 175 × 175 × 90 | G36: Hemispherical shell | H36: Outside Ø100 mm; depth 50 mm; nominal wall 3 mm; open equator | I36: ='Quantity grades'!G17 -> H13 | J36: Die preheat; internal temperature-control circuits and external spray | K36: Rectangular block | L36: 94 | M36: 94 | N36: 47 | O36: 0.006 | P36: 35 | Q36: 35 | R36: 35 | S36: 3 | T36: 5 | U36: =L36*(1+O36)+2*P36 -> 164.564 | V36: =IF(K36="Round billet","",M36*(1+O36)+2*Q36) -> 164.564 | W36: =N36*(1+O36)+R36 -> 82.282 | X36: =ROUNDUP((U36+2*S36)/T36,0)*T36 -> 175 | Y36: =IF(K36="Round billet","",ROUNDUP((V36+2*S36)/T36,0)*T36) -> 175 | Z36: =ROUNDUP((W36+2*S36)/T36,0)*T36 -> 90 | AA36: P03-Q1-C02 | AB36: Inner hemisphere Ø94 mm, height 47 mm. Base/shutoff and ejector layout must be validated.
A37: Die casting | B37: 21–100 | C37: Outer hemisphere cavity | D37: FEMALE | E37: 1 | F37: =IF(K37="Round billet","Ø"&X37&" × "&Z37,X37&" × "&Y37&" × "&Z37) -> 190 × 190 × 100 | G37: Hemispherical shell | H37: Outside Ø100 mm; depth 50 mm; nominal wall 3 mm; open equator | I37: ='Quantity grades'!G18 -> H13 | J37: Die preheat; internal temperature-control circuits and external spray | K37: Rectangular block | L37: 100 | M37: 100 | N37: 50 | O37: 0.006 | P37: 40 | Q37: 40 | R37: 40 | S37: 3 | T37: 5 | U37: =L37*(1+O37)+2*P37 -> 180.6 | V37: =IF(K37="Round billet","",M37*(1+O37)+2*Q37) -> 180.6 | W37: =N37*(1+O37)+R37 -> 90.3 | X37: =ROUNDUP((U37+2*S37)/T37,0)*T37 -> 190 | Y37: =IF(K37="Round billet","",ROUNDUP((V37+2*S37)/T37,0)*T37) -> 190 | Z37: =ROUNDUP((W37+2*S37)/T37,0)*T37 -> 100 | AA37: P03-Q2-C01 | AB37: 40 mm peripheral reserve for support and local feed/cooling layout; exact features not yet laid out.
A38: Die casting | B38: 21–100 | C38: Inner hemisphere core | D38: MALE | E38: 1 | F38: =IF(K38="Round billet","Ø"&X38&" × "&Z38,X38&" × "&Y38&" × "&Z38) -> 175 × 175 × 90 | G38: Hemispherical shell | H38: Outside Ø100 mm; depth 50 mm; nominal wall 3 mm; open equator | I38: ='Quantity grades'!G18 -> H13 | J38: Die preheat; internal temperature-control circuits and external spray | K38: Rectangular block | L38: 94 | M38: 94 | N38: 47 | O38: 0.006 | P38: 35 | Q38: 35 | R38: 35 | S38: 3 | T38: 5 | U38: =L38*(1+O38)+2*P38 -> 164.564 | V38: =IF(K38="Round billet","",M38*(1+O38)+2*Q38) -> 164.564 | W38: =N38*(1+O38)+R38 -> 82.282 | X38: =ROUNDUP((U38+2*S38)/T38,0)*T38 -> 175 | Y38: =IF(K38="Round billet","",ROUNDUP((V38+2*S38)/T38,0)*T38) -> 175 | Z38: =ROUNDUP((W38+2*S38)/T38,0)*T38 -> 90 | AA38: P03-Q2-C02 | AB38: Inner hemisphere Ø94 mm, height 47 mm. Base/shutoff and ejector layout must be validated.
A39: Die casting | B39: 101–1,000 | C39: Outer hemisphere cavity | D39: FEMALE | E39: 1 | F39: =IF(K39="Round billet","Ø"&X39&" × "&Z39,X39&" × "&Y39&" × "&Z39) -> 190 × 190 × 100 | G39: Hemispherical shell | H39: Outside Ø100 mm; depth 50 mm; nominal wall 3 mm; open equator | I39: ='Quantity grades'!G19 -> H13 | J39: Die preheat; internal temperature-control circuits and external spray | K39: Rectangular block | L39: 100 | M39: 100 | N39: 50 | O39: 0.006 | P39: 40 | Q39: 40 | R39: 40 | S39: 3 | T39: 5 | U39: =L39*(1+O39)+2*P39 -> 180.6 | V39: =IF(K39="Round billet","",M39*(1+O39)+2*Q39) -> 180.6 | W39: =N39*(1+O39)+R39 -> 90.3 | X39: =ROUNDUP((U39+2*S39)/T39,0)*T39 -> 190 | Y39: =IF(K39="Round billet","",ROUNDUP((V39+2*S39)/T39,0)*T39) -> 190 | Z39: =ROUNDUP((W39+2*S39)/T39,0)*T39 -> 100 | AA39: P03-Q3-C01 | AB39: 40 mm peripheral reserve for support and local feed/cooling layout; exact features not yet laid out.
A40: Die casting | B40: 101–1,000 | C40: Inner hemisphere core | D40: MALE | E40: 1 | F40: =IF(K40="Round billet","Ø"&X40&" × "&Z40,X40&" × "&Y40&" × "&Z40) -> 175 × 175 × 90 | G40: Hemispherical shell | H40: Outside Ø100 mm; depth 50 mm; nominal wall 3 mm; open equator | I40: ='Quantity grades'!G19 -> H13 | J40: Die preheat; internal temperature-control circuits and external spray | K40: Rectangular block | L40: 94 | M40: 94 | N40: 47 | O40: 0.006 | P40: 35 | Q40: 35 | R40: 35 | S40: 3 | T40: 5 | U40: =L40*(1+O40)+2*P40 -> 164.564 | V40: =IF(K40="Round billet","",M40*(1+O40)+2*Q40) -> 164.564 | W40: =N40*(1+O40)+R40 -> 82.282 | X40: =ROUNDUP((U40+2*S40)/T40,0)*T40 -> 175 | Y40: =IF(K40="Round billet","",ROUNDUP((V40+2*S40)/T40,0)*T40) -> 175 | Z40: =ROUNDUP((W40+2*S40)/T40,0)*T40 -> 90 | AA40: P03-Q3-C02 | AB40: Inner hemisphere Ø94 mm, height 47 mm. Base/shutoff and ejector layout must be validated.
A41: Die casting | B41: 1,001–10,000 | C41: Outer hemisphere cavity | D41: FEMALE | E41: 1 | F41: =IF(K41="Round billet","Ø"&X41&" × "&Z41,X41&" × "&Y41&" × "&Z41) -> 190 × 190 × 100 | G41: Hemispherical shell | H41: Outside Ø100 mm; depth 50 mm; nominal wall 3 mm; open equator | I41: ='Quantity grades'!G20 -> H13; ESR where required | J41: Die preheat; internal temperature-control circuits and external spray | K41: Rectangular block | L41: 100 | M41: 100 | N41: 50 | O41: 0.006 | P41: 40 | Q41: 40 | R41: 40 | S41: 3 | T41: 5 | U41: =L41*(1+O41)+2*P41 -> 180.6 | V41: =IF(K41="Round billet","",M41*(1+O41)+2*Q41) -> 180.6 | W41: =N41*(1+O41)+R41 -> 90.3 | X41: =ROUNDUP((U41+2*S41)/T41,0)*T41 -> 190 | Y41: =IF(K41="Round billet","",ROUNDUP((V41+2*S41)/T41,0)*T41) -> 190 | Z41: =ROUNDUP((W41+2*S41)/T41,0)*T41 -> 100 | AA41: P03-Q4-C01 | AB41: 40 mm peripheral reserve for support and local feed/cooling layout; exact features not yet laid out.
